<?xml version="1.0" encoding="UTF-8"?>
<!-- Generated by org.testng.reporters.JUnitReportReporter -->
<testsuite hostname="PC-BSAphoto" failures="1" tests="6" name="com.Sample.testobjects.SampleTest" time="118.485" errors="0" timestamp="08 Jun 2022 11:45:56 GMT" skipped="0">
  <testcase classname="com.Sample.testobjects.SampleTest" name="incorrectPassword" time="10.404"/>
  <testcase classname="com.Sample.testobjects.SampleTest" name="logOut" time="0.023">
    <failure message="expected [pass] but found [fail]" type="java.lang.AssertionError">
      <![CDATA[java.lang.AssertionError: expected [pass] but found [fail]
	at org.testng.Assert.fail(Assert.java:93)
	at org.testng.Assert.failNotEquals(Assert.java:512)
	at org.testng.Assert.assertEqualsImpl(Assert.java:134)
	at org.testng.Assert.assertEquals(Assert.java:115)
	at org.testng.Assert.assertEquals(Assert.java:178)
	at com.Sample.testobjects.SampleTest.logOut(SampleTest.java:177)
	at java.base/jdk.internal.reflect.NativeMethodAccessorImpl.invoke0(Native Method)
	at java.base/jdk.internal.reflect.NativeMethodAccessorImpl.invoke(NativeMethodAccessorImpl.java:64)
	at java.base/jdk.internal.reflect.DelegatingMethodAccessorImpl.invoke(DelegatingMethodAccessorImpl.java:43)
	at java.base/java.lang.reflect.Method.invoke(Method.java:564)
	at org.testng.internal.MethodInvocationHelper.invokeMethod(MethodInvocationHelper.java:108)
	at org.testng.internal.Invoker.invokeMethod(Invoker.java:661)
	at org.testng.internal.Invoker.invokeTestMethod(Invoker.java:869)
	at org.testng.internal.Invoker.invokeTestMethods(Invoker.java:1193)
	at org.testng.internal.TestMethodWorker.invokeTestMethods(TestMethodWorker.java:126)
	at org.testng.internal.TestMethodWorker.run(TestMethodWorker.java:109)
	at org.testng.TestRunner.privateRun(TestRunner.java:744)
	at org.testng.TestRunner.run(TestRunner.java:602)
	at org.testng.SuiteRunner.runTest(SuiteRunner.java:380)
	at org.testng.SuiteRunner.access$000(SuiteRunner.java:39)
	at org.testng.SuiteRunner$SuiteWorker.run(SuiteRunner.java:414)
	at org.testng.internal.thread.ThreadUtil$1.call(ThreadUtil.java:52)
	at java.base/java.util.concurrent.FutureTask.run(FutureTask.java:264)
	at java.base/java.util.concurrent.ThreadPoolExecutor.runWorker(ThreadPoolExecutor.java:1130)
	at java.base/java.util.concurrent.ThreadPoolExecutor$Worker.run(ThreadPoolExecutor.java:630)
	at java.base/java.lang.Thread.run(Thread.java:832)
]]>
    </failure>
  </testcase> <!-- logOut -->
  <testcase classname="com.Sample.testobjects.SampleTest" name="successfulLogIn" time="71.519"/>
  <testcase classname="com.Sample.testobjects.SampleTest" name="blankEmailOrNumberLogIn" time="17.822"/>
  <testcase classname="com.Sample.testobjects.SampleTest" name="noAccountFound" time="8.997"/>
  <testcase classname="com.Sample.testobjects.SampleTest" name="blankPassword" time="9.720"/>
</testsuite> <!-- com.Sample.testobjects.SampleTest -->
